Workbook

Sheet Outlier Visualization
A1: Outlier Visualization
A3: Master Data Product
A44: Master Data Sales Team
A67: Data Sales Order
A87: Data Order Item
A127: Data Invoice

Sheet Distribution & Skewness
A1: Master Data Product
A36: Master Data Sales Team
A53: Data Sales Order
A70: Data Order Item
A107: Data Invoice

Sheet Product
A1: ProductID | B1: VendorID | C1: Check for VendorID | D1: ProductName | E1: Category | F1: UnitSalesPrice | G1: UnitBuyPrice | H1: Margin per Product (UnitSalesPrice - UnitBuyerPrice) | I1: Quantity | J1: UOM | K1: DiscountProduct | L1: Product Description
A2: PD0001 | B2: VD0002 | C2: =VLOOKUP(B2,Vendor!A$2:B$4,1,0) -> VD0002 | D2: 1 Set Fishing Equipment | E2: Fishing Equipment | F2: 249000 | G2: 180000 | H2: =F2-G2 -> 69000 | I2: 12547 | J2: Set | K2: 0.3 | L2: Joran, Reel, Tas, Senar, Mata kail, Stoper, Starlet
A3: PD0002 | B3: VD0002 | C3: =VLOOKUP(B3,Vendor!A$2:B$4,1,0) -> VD0002 | D3: Fishing soft lure | E3: Fishing Equipment | F3: 20000 | G3: 14000 | H3: =F3-G3 -> 6000 | I3: 14769 | J3: Unit | K3: 0.1
A4: PD0003 | B4: VD0003 | C4: =VLOOKUP(B4,Vendor!A$2:B$4,1,0) -> VD0003 | D4: Stick Billiard | E4: Billiard | F4: 931000 | G4: 785000 | H4: =F4-G4 -> 146000 | I4: 5654 | J4: Unit | K4: 0.2 | L4: Tip Size : 11.75mm, dan Length : 148 cm
A5: PD0004 | B5: VD0003 | C5: =VLOOKUP(B5,Vendor!A$2:B$4,1,0) -> VD0003 | D5: Stick Billiard Bag | E5: Billiard | F5: 220000 | G5: 175000 | H5: =F5-G5 -> 45000 | I5: 3275 | J5: Unit | K5: 0.25
A6: PD0005 | B6: VD0001 | C6: =VLOOKUP(B6,Vendor!A$2:B$4,1,0) -> VD0001 | D6: Stick Golf Wedge | E6: Golf | F6: 2195000 | G6: 1785000 | H6: =F6-G6 -> 410000 | I6: 3431 | J6: Unit | K6: 0.2 | L6: Degree : 52, 56, 60, 64
A7: PD0006 | B7: VD0001 | C7: =VLOOKUP(B7,Vendor!A$2:B$4,1,0) -> VD0001 | D7: 1 set Golf Ball | E7: Golf | F7: 209000 | G7: 195000 | H7: =F7-G7 -> 14000 | I7: 8123 | J7: Set | K7: 0.2 | L7: 12 bola golf
A8: PD0007 | B8: VD0001 | C8: =VLOOKUP(B8,Vendor!A$2:B$4,1,0) -> VD0001 | D8: Stick Golf Bag | E8: Golf | F8: 3200000 | G8: 2800000 | H8: =F8-G8 -> 400000 | I8: 2288 | J8: Unit | K8: 0.2
A9: PD0008 | B9: VD0002 | C9: =VLOOKUP(B9,Vendor!A$2:B$4,1,0) -> VD0002 | D9: Sunglasses | E9: Outdoors Sport | F9: 149000 | G9: 118000 | H9: =F9-G9 -> 31000 | I9: 11023 | J9: Unit | K9: 0.15
A10: PD0009 | B10: VD0002 | C10: =VLOOKUP(B10,Vendor!A$2:B$4,1,0) -> VD0002 | D10: Tracking Pole | E10: Hiking & Camping | F10: 129000 | G10: 105000 | H10: =F10-G10 -> 24000 | I10: 1418 | J10: Unit | K10: 0.15 | L10: Ukuran untuk Anak - anak : 100 cm, dan Dewasa : 125 com
A11: PD0010 | B11: VD0002 | C11: =VLOOKUP(B11,Vendor!A$2:B$4,1,0) -> VD0002 | D11: Hiking Shoes | E11: Hiking & Camping | F11: 325000 | G11: 250000 | H11: =F11-G11 -> 75000 | I11: 3361 | J11: Unit | K11: 0.25 | L11: Size tersedia : 40/25.5cm - 44/29.5cm
A12: PD0011 | B12: VD0003 | C12: =VLOOKUP(B12,Vendor!A$2:B$4,1,0) -> VD0003 | D12: Mountain Bike | E12: Bicycle | F12: 2359000 | G12: 2000000 | H12: =F12-G12 -> 359000 | I12: 2393 | J12: Unit | K12: 0.2 | L12: Warna : Hitam Merah, Grey Orange, Teal, Hitam biru
A13: PD0012 | B13: VD0003 | C13: =VLOOKUP(B13,Vendor!A$2:B$4,1,0) -> VD0003 | D13: Road Bike | E13: Bicycle | F13: 5639000 | G13: 4800000 | H13: =F13-G13 -> 839000 | I13: 2710 | J13: Unit | K13: 0.2 | L13: Tipe Sepeda balap Performance dan All - around
A14: PD0013 | B14: VD0001 | C14: =VLOOKUP(B14,Vendor!A$2:B$4,1,0) -> VD0001 | D14: 1 Set Basketball | E14: Basketball | F14: 479000 | G14: 395000 | H14: =F14-G14 -> 84000 | I14: 17561 | J14: Set | K14: 0.3 | L14: 5 Bola Basket
A15: PD0014 | B15: VD0001 | C15: =VLOOKUP(B15,Vendor!A$2:B$4,1,0) -> VD0001 | D15: 1 Set Futsalball | E15: Futsal | F15: 267000 | G15: 225000 | H15: =F15-G15 -> 42000 | I15: 17743 | J15: Set | K15: 0.3 | L15: 5 Bola Futsal
A16: PD0015 | B16: VD0002 | C16: =VLOOKUP(B16,Vendor!A$2:B$4,1,0) -> VD0002 | D16: Abs Roller | E16: Gym & Fitness | F16: 135900 | G16: 95000 | H16: =F16-G16 -> 40900 | I16: 3479 | J16: Unit | K16: 0.25
A17: PD0016 | B17: VD0002 | C17: =VLOOKUP(B17,Vendor!A$2:B$4,1,0) -> VD0002 | D17: Pull Up Bar | E17: Gym & Fitness | F17: 267000 | G17: 210000 | H17: =F17-G17 -> 57000 | I17: 5101 | J17: Unit | K17: 0.25 | L17: Size : 80-130 cm
A18: PD0017 | B18: VD0002 | C18: =VLOOKUP(B18,Vendor!A$2:B$4,1,0) -> VD0002 | D18: Bench Press | E18: Gym & Fitness | F18: 2650000 | G18: 2200000 | H18: =F18-G18 -> 450000 | I18: 2546 | J18: Unit | K18: 0.1 | L18: Dimensi : 142 x 110 x 108 cm
A19: PD0018 | B19: VD0002 | C19: =VLOOKUP(B19,Vendor!A$2:B$4,1,0) -> VD0002 | D19: Dumbell Set | E19: Gym & Fitness | F19: 532000 | G19: 485000 | H19: =F19-G19 -> 47000 | I19: 11648 | J19: Unit | K19: 0.1 | L19: 2x 35cm (14") Stick Chrome, 1 pcs 152cm Stick, 6pcs Collar pengunci, 4pcs 1 kg plates, 2pcs 2 kg, 2pcs kg
A20: PD0019 | B20: VD0001 | C20: =VLOOKUP(B20,Vendor!A$2:B$4,1,0) -> VD0001 | D20: Treadmill | E20: Gym & Fitness | F20: 2549000 | G20: 2250000 | H20: =F20-G20 -> 299000 | I20: 3106 | J20: Unit | K20: 0.25
A21: PD0020 | B21: VD0001 | C21: =VLOOKUP(B21,Vendor!A$2:B$4,1,0) -> VD0001 | D21: Heavy bag | E21: Gym & Fitness | F21: 321000 | G21: 275000 | H21: =F21-G21 -> 46000 | I21: 3151 | J21: Unit | K21: 0.25

Sheet Vendor
A1: VendorID | B1: VendorName | C1: Address | D1: City | E1: Province | F1: Email | G1: Phone
A2: VD0001 | B2: PT.Aneka Olahraga | C2: Jl. Tanjong Priok No.23 | D2: North Jakarta | E2: Jakarta | F2: Anekasport@net.id | G2: +62 87 1651 6391
A3: VD0002 | B3: Sportspirit Inc | C3: Ubi Ave Street No.3 | D3: Singapore City | E3: Singapore | F3: sportspirit.co.id | G3: +65 8249 7112
A4: VD0003 | B4: PT.Fortune Sport | C4: Jl. Gajah Mada No.78 | D4: Central Jakarta | E4: Jakarta | F4: fortunesport.com | G4: +62 82 2497 3691

Sheet Patner Store
A1: PatnerStoreID | B1: PatnerStoreName | C1: PatnerType | D1: Region | E1: Province | F1: PatnerContactPhone
A2: PS0001 | B2: Sport Nation | C2: Distributor | D2: Bali | E2: Bali | F2: +62 837 3881 3393
A3: PS0002 | B3: TokoSport | C3: Retail | D3: Java | E3: East Java | F3: +62 843 0014 8341
A4: PS0003 | B4: Toko Gelora Sport | C4: Retail | D4: Kalimantan | E4: Central Kalimantan | F4: +62 856 3951 0850
A5: PS0004 | B5: Sport Line Indonesia | C5: Retail | D5: Java | E5: Jakarta | F5: +62 844 6558 9313
A6: PS0005 | B6: Sportworld | C6: Distributor | D6: Sulawesi | E6: South Sulawesi | F6: +62 834 8087 5084
A7: PS0006 | B7: Arena Sport Shop | C7: Retail | D7: Kalimantan | E7: Central Kalimantan | F7: +62 897 3528 4125
A8: PS0007 | B8: Twinsport.com | C8: Retail | D8: Java | E8: Jakarta | F8: +62 809 1899 6494
A9: PS0008 | B9: Amanah Sport | C9: Retail | D9: Sulawesi | E9: North Sulawesi | F9: +62 854 5164 5861
A10: PS0009 | B10: Olahraga Mall | C10: Distributor | D10: Sumatera | E10: South Sumatera | F10: +62 888 2771 3218
A11: PS0010 | B11: WorldSport.com | C11: Retail | D11: Java | E11: Jakarta | F11: +62 824 4696 3312
A12: PS0011 | B12: Atlethic Shop | C12: Retail | D12: Java | E12: East Java | F12: +62 878 0243 7778
... A51: PS0050 | B51: Toko Peralatan Olahraga | C51: Retail | D51: Maluku | E51: Maluku | F51: +62 888 9236 8417

Sheet Sales Team
A1: SalesTeamID | B1: SalesTeamName | C1: SalesTeamRegion | D1: SalesPromotionMethods | E1: TotalProspect
A2: ST0001 | B2: Online Sales Team | C2: Jakarta | D2: OnlineMarketing | E2: 10
A3: ST0002 | B3: Sales Java Region Team | C3: Java | D3: OnlineMarketing/Corporate Negotiate/Patnership Contract | E3: 6
A4: ST0003 | B4: Sales Sumatera -Kalimantan Region Team | C4: Sumatera & Kalimantan | D4: OnlineMarketing/Corporate Negotiate/Patnership Contract | E4: 12
A5: ST0004 | B5: Sales Region Sulawesi - Maluku Team | C5: Sulawesi, Maluku, North Maluku | D5: Corporate Negotiate/Patnership Contract | E5: 16
A6: ST0005 | B6: Sales Region Bali - Nusa Tenggara Team | C6: Bali, East & West Nusa Tenggara | D6: Corporate Negotiate/Patnership Contract | E6: 6

Sheet Sales Order
A1: SalesOrderID | B1: PatnerStoreID | C1: Check PatnerStoreID | D1: SalesTeamID | E1: Check SalesTeamID | F1: OrderDate | G1: Payment | H1: TotalOrderTransaction | I1: Note
A2: SO0001 | B2: PS0040 | C2: =VLOOKUP(B2,'Patner Store'!A$2:A$51,1,0) -> PS0040 | D2: ST0003 | E2: =VLOOKUP(D2,'Sales Team'!A$2:B$6,1,0) -> ST0003 | F2: 43832 | G2: CASH | H2: 114641676
A3: SO0002 | B3: PS0046 | C3: =VLOOKUP(B3,'Patner Store'!A$2:A$51,1,0) -> PS0046 | D3: ST0003 | E3: =VLOOKUP(D3,'Sales Team'!A$2:B$6,1,0) -> ST0003 | F3: 43832 | G3: CASH | H3: 44870970
A4: SO0003 | B4: PS0024 | C4: =VLOOKUP(B4,'Patner Store'!A$2:A$51,1,0) -> PS0024 | D4: ST0001 | E4: =VLOOKUP(D4,'Sales Team'!A$2:B$6,1,0) -> ST0001 | F4: 43833 | G4: CREDIT | H4: 1101806050 | I4: transaction as agreed with the vendor
A5: SO0004 | B5: PS0048 | C5: =VLOOKUP(B5,'Patner Store'!A$2:A$51,1,0) -> PS0048 | D5: ST0003 | E5: =VLOOKUP(D5,'Sales Team'!A$2:B$6,1,0) -> ST0003 | F5: 43834 | G5: CASH | H5: 10698048
A6: SO0005 | B6: PS0024 | C6: =VLOOKUP(B6,'Patner Store'!A$2:A$51,1,0) -> PS0024 | D6: ST0001 | E6: =VLOOKUP(D6,'Sales Team'!A$2:B$6,1,0) -> ST0001 | F6: 43835 | G6: CREDIT | H6: 250560000
A7: SO0006 | B7: PS0012 | C7: =VLOOKUP(B7,'Patner Store'!A$2:A$51,1,0) -> PS0012 | D7: ST0003 | E7: =VLOOKUP(D7,'Sales Team'!A$2:B$6,1,0) -> ST0003 | F7: 43837 | G7: CASH | H7: 11269440
A8: SO0007 | B8: PS0024 | C8: =VLOOKUP(B8,'Patner Store'!A$2:A$51,1,0) -> PS0024 | D8: ST0001 | E8: =VLOOKUP(D8,'Sales Team'!A$2:B$6,1,0) -> ST0001 | F8: 43839 | G8: CREDIT | H8: 427027780
A9: SO0008 | B9: PS0045 | C9: =VLOOKUP(B9,'Patner Store'!A$2:A$51,1,0) -> PS0045 | D9: ST0005 | E9: =VLOOKUP(D9,'Sales Team'!A$2:B$6,1,0) -> ST0005 | F9: 43840 | G9: CREDIT | H9: 614116940
A10: SO0009 | B10: PS0037 | C10: =VLOOKUP(B10,'Patner Store'!A$2:A$51,1,0) -> PS0037 | D10: ST0002 | E10: =VLOOKUP(D10,'Sales Team'!A$2:B$6,1,0) -> ST0002 | F10: 43841 | G10: CASH | H10: 175419850
A11: SO0010 | B11: PS0037 | C11: =VLOOKUP(B11,'Patner Store'!A$2:A$51,1,0) -> PS0037 | D11: ST0002 | E11: =VLOOKUP(D11,'Sales Team'!A$2:B$6,1,0) -> ST0002 | F11: 43841 | G11: CREDIT | H11: 669084987
A12: SO0011 | B12: PS0003 | C12: =VLOOKUP(B12,'Patner Store'!A$2:A$51,1,0) -> PS0003 | D12: ST0003 | E12: =VLOOKUP(D12,'Sales Team'!A$2:B$6,1,0) -> ST0003 | F12: 43843 | G12: CASH | H12: 70191310 | I12: The transaction agreement has undergone changes
A13: SO0012 | B13: PS0043 | C13: =VLOOKUP(B13,'Patner Store'!A$2:A$51,1,0) -> PS0043 | D13: ST0004 | E13: =VLOOKUP(D13,'Sales Team'!A$2:B$6,1,0) -> ST0004 | F13: 43847 | G13: CASH | H13: 97549900
A14: SO0013 | B14: PS0050 | C14: =VLOOKUP(B14,'Patner Store'!A$2:A$51,1,0) -> PS0050 | D14: ST0004 | E14: =VLOOKUP(D14,'Sales Team'!A$2:B$6,1,0) -> ST0004 | F14: 43848 | G14: CREDIT | H14: 637102960
A15: SO0014 | B15: PS0032 | C15: =VLOOKUP(B15,'Patner Store'!A$2:A$51,1,0) -> PS0032 | D15: ST0004 | E15: =VLOOKUP(D15,'Sales Team'!A$2:B$6,1,0) -> ST0004 | F15: 43849 | G15: CREDIT | H15: 290103980
A16: SO0015 | B16: PS0014 | C16: =VLOOKUP(B16,'Patner Store'!A$2:A$51,1,0) -> PS0014 | D16: ST0003 | E16: =VLOOKUP(D16,'Sales Team'!A$2:B$6,1,0) -> ST0003 | F16: 43850 | G16: CREDIT | H16: 644706190 | I16: transaction as agreed with the vendor
A17: SO0016 | B17: PS0008 | C17: =VLOOKUP(B17,'Patner Store'!A$2:A$51,1,0) -> PS0008 | D17: ST0004 | E17: =VLOOKUP(D17,'Sales Team'!A$2:B$6,1,0) -> ST0004 | F17: 43850 | G17: CASH | H17: 248020740 | I17: Partner Store canceled the order
A18: SO0017 | B18: PS0013 | C18: =VLOOKUP(B18,'Patner Store'!A$2:A$51,1,0) -> PS0013 | D18: ST0001 | E18: =VLOOKUP(D18,'Sales Team'!A$2:B$6,1,0) -> ST0001 | F18: 43853 | G18: CREDIT | H18: 688063360
A19: SO0018 | B19: PS0039 | C19: =VLOOKUP(B19,'Patner Store'!A$2:A$51,1,0) -> PS0039 | D19: ST0003 | E19: =VLOOKUP(D19,'Sales Team'!A$2:B$6,1,0) -> ST0003 | F19: 43853 | G19: CASH | H19: 44061600
A20: SO0019 | B20: PS0020 | C20: =VLOOKUP(B20,'Patner Store'!A$2:A$51,1,0) -> PS0020 | D20: ST0004 | E20: =VLOOKUP(D20,'Sales Team'!A$2:B$6,1,0) -> ST0004 | F20: 43854 | G20: CREDIT | H20: 301033270
A21: SO0020 | B21: PS0019 | C21: =VLOOKUP(B21,'Patner Store'!A$2:A$51,1,0) -> PS0019 | D21: ST0005 | E21: =VLOOKUP(D21,'Sales Team'!A$2:B$6,1,0) -> ST0005 | F21: 43856 | G21: CASH | H21: 70487380
A22: SO0021 | B22: PS0037 | C22: =VLOOKUP(B22,'Patner Store'!A$2:A$51,1,0) -> PS0037 | D22: ST0002 | E22: =VLOOKUP(D22,'Sales Team'!A$2:B$6,1,0) -> ST0002 | F22: 43856 | G22: CASH | H22: 219754110
A23: SO0022 | B23: PS0018 | C23: =VLOOKUP(B23,'Patner Store'!A$2:A$51,1,0) -> PS0018 | D23: ST0002 | E23: =VLOOKUP(D23,'Sales Team'!A$2:B$6,1,0) -> ST0002 | F23: 43856 | G23: CREDIT | H23: 473835924 | I23: The product is unavailable from the vendor or there has been a product replacement
A24: SO0023 | B24: PS0013 | C24: =VLOOKUP(B24,'Patner Store'!A$2:A$51,1,0) -> PS0013 | D24: ST0001 | E24: =VLOOKUP(D24,'Sales Team'!A$2:B$6,1,0) -> ST0001 | F24: 43857 | G24: CASH | H24: 177937976
A25: SO0024 | B25: PS0040 | C25: =VLOOKUP(B25,'Patner Store'!A$2:A$51,1,0) -> PS0040 | D25: ST0003 | E25: =VLOOKUP(D25,'Sales Team'!A$2:B$6,1,0) -> ST0003 | F25: 43859 | G25: CASH | H25: 43468350
A26: SO0025 | B26: PS0034 | C26: =VLOOKUP(B26,'Patner Store'!A$2:A$51,1,0) -> PS0034 | D26: ST0001 | E26: =VLOOKUP(D26,'Sales Team'!A$2:B$6,1,0) -> ST0001 | F26: 43860 | G26: CASH | H26: 72692150
A27: SO0026 | B27: PS0021 | C27: =VLOOKUP(B27,'Patner Store'!A$2:A$51,1,0) -> PS0021 | D27: ST0001 | E27: =VLOOKUP(D27,'Sales Team'!A$2:B$6,1,0) -> ST0001 | F27: 43861 | G27: CASH | H27: 249589510 | I27: The product is unavailable from the vendor or there has been a product replacement
A28: SO0027 | B28: PS0047 | C28: =VLOOKUP(B28,'Patner Store'!A$2:A$51,1,0) -> PS0047 | D28: ST0001 | E28: =VLOOKUP(D28,'Sales Team'!A$2:B$6,1,0) -> ST0001 | F28: 43861 | G28: CREDIT | H28: 665340650 | I28: transaction as agreed with the vendor
A29: SO0028 | B29: PS0035 | C29: =VLOOKUP(B29,'Patner Store'!A$2:A$51,1,0) -> PS0035 | D29: ST0004 | E29: =VLOOKUP(D29,'Sales Team'!A$2:B$6,1,0) -> ST0004 | F29: 43866 | G29: CASH | H29: 110695360 | I29: Partner Store canceled the order
A30: SO0029 | B30: PS0028 | C30: =VLOOKUP(B30,'Patner Store'!A$2:A$51,1,0) -> PS0028 | D30: ST0005 | E30: =VLOOKUP(D30,'Sales Team'!A$2:B$6,1,0) -> ST0005 | F30: 43866 | G30: CASH | H30: 48219680
A31: SO0030 | B31: PS0022 | C31: =VLOOKUP(B31,'Patner Store'!A$2:A$51,1,0) -> PS0022 | D31: ST0004 | E31: =VLOOKUP(D31,'Sales Team'!A$2:B$6,1,0) -> ST0004 | F31: 43868 | G31: CASH | H31: 80974010
A32: SO0031 | B32: PS0007 | C32: =VLOOKUP(B32,'Patner Store'!A$2:A$51,1,0) -> PS0007 | D32: ST0001 | E32: =VLOOKUP(D32,'Sales Team'!A$2:B$6,1,0) -> ST0001 | F32: 43874 | G32: CASH | H32: 21634158 | I32: The transaction agreement has undergone changes
A33: SO0032 | B33: PS0010 | C33: =VLOOKUP(B33,'Patner Store'!A$2:A$51,1,0) -> PS0010 | D33: ST0001 | E33: =VLOOKUP(D33,'Sales Team'!A$2:B$6,1,0) -> ST0001 | F33: 43875 | G33: CASH | H33: 38254350
A34: SO0033 | B34: PS0012 | C34: =VLOOKUP(B34,'Patner Store'!A$2:A$51,1,0) -> PS0012 | D34: ST0003 | E34: =VLOOKUP(D34,'Sales Team'!A$2:B$6,1,0) -> ST0003 | F34: 43875 | G34: CREDIT | H34: 274768110 | I34: The transaction agreement has undergone changes
A35: SO0034 | B35: PS0001 | C35: =VLOOKUP(B35,'Patner Store'!A$2:A$51,1,0) -> PS0001 | D35: ST0005 | E35: =VLOOKUP(D35,'Sales Team'!A$2:B$6,1,0) -> ST0005 | F35: 43876 | G35: CASH | H35: 156249110
A36: SO0035 | B36: PS0033 | C36: =VLOOKUP(B36,'Patner Store'!A$2:A$51,1,0) -> PS0033 | D36: ST0005 | E36: =VLOOKUP(D36,'Sales Team'!A$2:B$6,1,0) -> ST0005 | F36: 43877 | G36: CREDIT | H36: 473491910
A37: SO0036 | B37: PS0034 | C37: =VLOOKUP(B37,'Patner Store'!A$2:A$51,1,0) -> PS0034 | D37: ST0001 | E37: =VLOOKUP(D37,'Sales Team'!A$2:B$6,1,0) -> ST0001 | F37: 43878 | G37: CREDIT | H37: 376525700
A38: SO0037 | B38: PS0028 | C38: =VLOOKUP(B38,'Patner Store'!A$2:A$51,1,0) -> PS0028 | D38: ST0005 | E38: =VLOOKUP(D38,'Sales Team'!A$2:B$6,1,0) -> ST0005 | F38: 43881 | G38: CREDIT | H38: 1038581420 | I38: transaction as agreed with the vendor
A39: SO0038 | B39: PS0036 | C39: =VLOOKUP(B39,'Patner Store'!A$2:A$51,1,0) -> PS0036 | D39: ST0005 | E39: =VLOOKUP(D39,'Sales Team'!A$2:B$6,1,0) -> ST0005 | F39: 43882 | G39: CASH | H39: 130531820
A40: SO0039 | B40: PS0013 | C40: =VLOOKUP(B40,'Patner Store'!A$2:A$51,1,0) -> PS0013 | D40: ST0001 | E40: =VLOOKUP(D40,'Sales Team'!A$2:B$6,1,0) -> ST0001 | F40: 43883 | G40: CREDIT | H40: 1115480621 | I40: transaction as agreed with the vendor
...

Sheet Order Item
A1: SalesOrderID | B1: Check SalesOrderID | C1: ProductID | D1: Check ProductID | E1: QuantityOrder | F1: ItemTotal | G1: OrderItemID
A2: SO0001 | B2: =VLOOKUP(A2,'Sales Order'!A$2:B$1029,1,0) -> SO0001 | C2: PD0002 | D2: =VLOOKUP(C2,Product!A$2:B$21,1,0) -> PD0002 | E2: 99 | F2: 1841400 | G2: SO0001-PD0002
A3: SO0001 | B3: =VLOOKUP(A3,'Sales Order'!A$2:B$1029,1,0) -> SO0001 | C3: PD0015 | D3: =VLOOKUP(C3,Product!A$2:B$21,1,0) -> PD0015 | E3: 89 | F3: 9192276 | G3: SO0001-PD0015
A4: SO0001 | B4: =VLOOKUP(A4,'Sales Order'!A$2:B$1029,1,0) -> SO0001 | C4: PD0011 | D4: =VLOOKUP(C4,Product!A$2:B$21,1,0) -> PD0011 | E4: 45 | F4: 93416400 | G4: SO0001-PD0011
A5: SO0001 | B5: =VLOOKUP(A5,'Sales Order'!A$2:B$1029,1,0) -> SO0001 | C5: PD0008 | D5: =VLOOKUP(C5,Product!A$2:B$21,1,0) -> PD0008 | E5: 72 | F5: 10191600 | G5: SO0001-PD0008
A6: SO0002 | B6: =VLOOKUP(A6,'Sales Order'!A$2:B$1029,1,0) -> SO0002 | C6: PD0014 | D6: =VLOOKUP(C6,Product!A$2:B$21,1,0) -> PD0014 | E6: 77 | F6: 17063970 | G6: SO0002-PD0014
A7: SO0002 | B7: =VLOOKUP(A7,'Sales Order'!A$2:B$1029,1,0) -> SO0002 | C7: PD0010 | D7: =VLOOKUP(C7,Product!A$2:B$21,1,0) -> PD0010 | E7: 92 | F7: 27807000 | G7: SO0002-PD0010
A8: SO0003 | B8: =VLOOKUP(A8,'Sales Order'!A$2:B$1029,1,0) -> SO0003 | C8: PD0011 | D8: =VLOOKUP(C8,Product!A$2:B$21,1,0) -> PD0011 | E8: 142 | F8: 291430860 | G8: SO0003-PD0011
A9: SO0003 | B9: =VLOOKUP(A9,'Sales Order'!A$2:B$1029,1,0) -> SO0003 | C9: PD0018 | D9: =VLOOKUP(C9,Product!A$2:B$21,1,0) -> PD0018 | E9: 125 | F9: 51870000 | G9: SO0003-PD0018
A10: SO0003 | B10: =VLOOKUP(A10,'Sales Order'!A$2:B$1029,1,0) -> SO0003 | C10: PD0010 | D10: =VLOOKUP(C10,Product!A$2:B$21,1,0) -> PD0010 | E10: 150 | F10: 44850000 | G10: SO0003-PD0010
A11: SO0003 | B11: =VLOOKUP(A11,'Sales Order'!A$2:B$1029,1,0) -> SO0003 | C11: PD0008 | D11: =VLOOKUP(C11,Product!A$2:B$21,1,0) -> PD0008 | E11: 94 | F11: 12885520 | G11: SO0003-PD0008
A12: SO0003 | B12: =VLOOKUP(A12,'Sales Order'!A$2:B$1029,1,0) -> SO0003 | C12: PD0012 | D12: =VLOOKUP(C12,Product!A$2:B$21,1,0) -> PD0012 | E12: 128 | F12: 671266560 | G12: SO0003-PD0012
A13: SO0003 | B13: =VLOOKUP(A13,'Sales Order'!A$2:B$1029,1,0) -> SO0003 | C13: PD0020 | D13: =VLOOKUP(C13,Product!A$2:B$21,1,0) -> PD0020 | E13: 101 | F13: 29503110 | G13: SO0003-PD0020
... A3393: SO1027 | B3393: =VLOOKUP(A3393,'Sales Order'!A$2:B$1029,1,0) -> SO1027 | C3393: PD0007 | D3393: =VLOOKUP(C3393,Product!A$2:B$21,1,0) -> PD0007 | E3393: 121 | F3393: 367840000 | G3393: SO1027-PD0007
F3395: =SUM(F2:F3393) -> 296769900803

Sheet Invoice
A1: InvoiceID | B1: SalesOrderID | C1: Check SalesOrderID | D1: ShipmentType | E1: WarehouseLocation | F1: TermsofPayment | G1: ShippingCost | H1: Taxes | I1: TotalDue | J1: TotalDueCheckCalculation
A2: IV0001 | B2: SO0001 | C2: =VLOOKUP(B2,'Sales Order'!A$2:B$1029,1,0) -> SO0001 | D2: Cargo | E2: Central Kalimantan | F2: COD | G2: 808800 | H2: 0.11 | I2: 1.2806106e+08 | J2: ='Sales Order'!H2+('Sales Order'!H2*0.11)+Invoice!G2 -> 1.2806106e+08
A3: IV0002 | B3: SO0002 | C3: =VLOOKUP(B3,'Sales Order'!A$2:B$1029,1,0) -> SO0002 | D3: Cargo | E3: South Kalimantan | F3: COD | G3: 808800 | H3: 0.11 | I3: 50615577 | J3: ='Sales Order'!H3+('Sales Order'!H3*0.11)+Invoice!G3 -> 50615577
A4: IV0003 | B4: SO0003 | C4: =VLOOKUP(B4,'Sales Order'!A$2:B$1029,1,0) -> SO0003 | D4: Reguler | E4: Jakarta | F4: NET60 | G4: 8088 | H4: 0.11 | I4: 1.2230128e+09 | J4: ='Sales Order'!H4+('Sales Order'!H4*0.11)+Invoice!G4 -> 1.2230128e+09
A5: IV0004 | B5: SO0004 | C5: =VLOOKUP(B5,'Sales Order'!A$2:B$1029,1,0) -> SO0004 | D5: Cargo | E5: South Kalimantan | F5: COD | G5: 808800 | H5: 0.11 | I5: 12683633 | J5: ='Sales Order'!H5+('Sales Order'!H5*0.11)+Invoice!G5 -> 12683633
A6: IV0005 | B6: SO0005 | C6: =VLOOKUP(B6,'Sales Order'!A$2:B$1029,1,0) -> SO0005 | D6: Reguler | E6: Jakarta | F6: NET60 | G6: 8088 | H6: 0.11 | I6: 278129688 | J6: ='Sales Order'!H6+('Sales Order'!H6*0.11)+Invoice!G6 -> 278129688
A7: IV0006 | B7: SO0006 | C7: =VLOOKUP(B7,'Sales Order'!A$2:B$1029,1,0) -> SO0006 | D7: Cargo | E7: South Kalimantan | F7: COD | G7: 808800 | H7: 0.11 | I7: 13317878 | J7: ='Sales Order'!H7+('Sales Order'!H7*0.11)+Invoice!G7 -> 13317878
A8: IV0007 | B8: SO0007 | C8: =VLOOKUP(B8,'Sales Order'!A$2:B$1029,1,0) -> SO0007 | D8: Reguler | E8: Jakarta | F8: NET90 | G8: 8088 | H8: 0.11 | I8: 4.7400892e+08 | J8: ='Sales Order'!H8+('Sales Order'!H8*0.11)+Invoice!G8 -> 4.7400892e+08
A9: IV0008 | B9: SO0008 | C9: =VLOOKUP(B9,'Sales Order'!A$2:B$1029,1,0) -> SO0008 | D9: Cargo | E9: West Nusa Tenggara | F9: NET90 | G9: 556050 | H9: 0.11 | I9: 6.8222585e+08 | J9: ='Sales Order'!H9+('Sales Order'!H9*0.11)+Invoice!G9 -> 6.8222585e+08
A10: IV0009 | B10: SO0009 | C10: =VLOOKUP(B10,'Sales Order'!A$2:B$1029,1,0) -> SO0009 | D10: Reguler | E10: East Java | F10: CBD | G10: 32352 | H10: 0.11 | I10: 1.9474839e+08 | J10: ='Sales Order'!H10+('Sales Order'!H10*0.11)+Invoice!G10 -> 1.9474839e+08
A11: IV0010 | B11: SO0010 | C11: =VLOOKUP(B11,'Sales Order'!A$2:B$1029,1,0) -> SO0010 | D11: Reguler | E11: East Java | F11: NET90 | G11: 32352 | H11: 0.11 | I11: 7.4271669e+08 | J11: ='Sales Order'!H11+('Sales Order'!H11*0.11)+Invoice!G11 -> 7.4271669e+08
A12: IV0011 | B12: SO0011 | C12: =VLOOKUP(B12,'Sales Order'!A$2:B$1029,1,0) -> SO0011 | D12: Cargo | E12: Central Kalimantan | F12: COD | G12: 808800 | H12: 0.11 | I12: 78721154 | J12: ='Sales Order'!H12+('Sales Order'!H12*0.11)+Invoice!G12 -> 78721154
A13: IV0012 | B13: SO0012 | C13: =VLOOKUP(B13,'Sales Order'!A$2:B$1029,1,0) -> SO0012 | D13: Cargo | E13: North Maluku | F13: COD | G13: 859350 | H13: 0.11 | I13: 109139739 | J13: ='Sales Order'!H13+('Sales Order'!H13*0.11)+Invoice!G13 -> 109139739
... A1029: IV1028 | B1029: SO1028 | C1029: =VLOOKUP(B1029,'Sales Order'!A$2:B$1029,1,0) -> SO1028 | D1029: Reguler | E1029: East Java | F1029: NET90 | G1029: 32352 | H1029: 0.11 | I1029: 533399229 | J1029: ='Sales Order'!H1029+('Sales Order'!H1029*0.11)+Invoice!G1029 -> 533399229
I1030: =SUM(I2:I1029) -> 3.2997113e+11 | J1030: =SUM(J2:J1029) -> 3.2997113e+11
